Workbook

Sheet Inputs
A1: Plantilla final de planificación - Coctel (Delibanquetes)
A3: Escenario A (bajo) - Invitados | B3: 400
A4: Escenario B (alto) - Invitados | B4: 500
A6: Bocas saladas por invitado | B6: 8
A7: Bocas dulces por invitado | B7: 2
A8: Mínimo por variedad (hard constraint proveedor) | B8: 50
A9: Servicio (% adicional del proveedor) | B9: 0.1
A11: Notas / reglas del proveedor
A12: - 10 bocas mínimo por persona - Selección mínima de 50 bocas por variedad - Máximo de 10 variedades (entre saladas, dulces, calientes o frías) - Agregar 10% de servicio
A14: Base del menú final recomendado
A15: - Día 1: 8 saladas distintas + 2 dulces - Día 2: 8 saladas distintas + 2 dulces - 0 repeticiones entre días - Precios base cargados desde el menú PDF compartido de Delibanquetes

Sheet Menu_Setup
A1: Curación de menú y asignación por día
A2: Boca / Variedad | B2: Sabor | C2: Tipo | D2: Precio unitario | E2: Notas | F2: Día 1 - porciones/invitado | G2: Día 2 - porciones/invitado | H2: Chequeo no duplicar
A3: Brocheta caprese con pesto | B3: Salado | C3: I | D3: 1.4 | F3: 1 | G3: 0 | H3: =IF(AND(F3>0,G3>0),"ERROR: en ambos días","")
A4: Bolitas de papa rellena de queso | B4: Salado | C4: I | D4: 1.4 | F4: 1 | G4: 0 | H4: =IF(AND(F4>0,G4>0),"ERROR: en ambos días","")
A5: Hongos al ajillo | B5: Salado | C5: I | D5: 1.4 | F5: 1 | G5: 0 | H5: =IF(AND(F5>0,G5>0),"ERROR: en ambos días","")
A6: Mini quiché de espinaca y queso | B6: Salado | C6: I | D6: 1.4 | F6: 1 | G6: 0 | H6: =IF(AND(F6>0,G6>0),"ERROR: en ambos días","")
A7: Crostini de melocotones asados y queso roquefort | B7: Salado | C7: II | D7: 1.7 | F7: 1 | G7: 0 | H7: =IF(AND(F7>0,G7>0),"ERROR: en ambos días","")
A8: Crostini de cebollas caramelizadas en maple con peras y queso brie | B8: Salado | C8: II | D8: 1.7 | F8: 1 | G8: 0 | H8: =IF(AND(F8>0,G8>0),"ERROR: en ambos días","")
A9: Costilla de cerdo en salsa barbacoa | B9: Salado | C9: II | D9: 1.7 | E9: Confirmar forma de servicio (porción / bocado). | F9: 1 | G9: 0 | H9: =IF(AND(F9>0,G9>0),"ERROR: en ambos días","")
A10: Bagel de salmón | B10: Salado | C10: Gourmet | D10: 2 | F10: 0 | G10: 1 | H10: =IF(AND(F10>0,G10>0),"ERROR: en ambos días","")
A11: Mini ceviche de pescado peruano | B11: Salado | C11: Gourmet | D11: 2 | F11: 0 | G11: 1 | H11: =IF(AND(F11>0,G11>0),"ERROR: en ambos días","")
A12: Mini ceviche de camarón | B12: Salado | C12: Gourmet | D12: 2 | F12: 0 | G12: 1 | H12: =IF(AND(F12>0,G12>0),"ERROR: en ambos días","")
A13: Brocheta de pollo al estilo Thai | B13: Salado | C13: Gourmet | D13: 2 | F13: 1 | G13: 0 | H13: =IF(AND(F13>0,G13>0),"ERROR: en ambos días","")
A14: Camarones empanizados con salsa tártara | B14: Salado | C14: Gourmet | D14: 2 | F14: 0 | G14: 1 | H14: =IF(AND(F14>0,G14>0),"ERROR: en ambos días","")
A15: Mini filet mignon | B15: Salado | C15: Gourmet | D15: 2 | E15: Confirmar cómo se sirve (corte / salsa). | F15: 0 | G15: 1 | H15: =IF(AND(F15>0,G15>0),"ERROR: en ambos días","")
A16: Rollitos de pepino o de berenjenas | B16: Salado | C16: Vegetarianos | D16: 2.25 | F16: 0 | G16: 1 | H16: =IF(AND(F16>0,G16>0),"ERROR: en ambos días","")
A17: Vegetales temporizados o tomates cherry confitados | B17: Salado | C17: Vegetarianos | D17: 2.25 | F17: 0 | G17: 1 | H17: =IF(AND(F17>0,G17>0),"ERROR: en ambos días","")
A18: Humus de colores | B18: Salado | C18: Vegetarianos | D18: 2.25 | F18: 0 | G18: 1 | H18: =IF(AND(F18>0,G18>0),"ERROR: en ambos días","")
A19: Cardenal de fruta roja (preferible fresa) | B19: Dulce | C19: Dulce | D19: 1.4 | F19: 1 | G19: 0 | H19: =IF(AND(F19>0,G19>0),"ERROR: en ambos días","")
A20: Fresas cubiertas con chocolate | B20: Dulce | C20: Dulce | D20: 1.4 | F20: 0 | G20: 1 | H20: =IF(AND(F20>0,G20>0),"ERROR: en ambos días","")
A21: Mini tartas / mini alfajores | B21: Dulce | C21: Dulce | D21: 1.4 | E21: (Reserva / reemplazo opcional). | F21: 0 | G21: 0 | H21: =IF(AND(F21>0,G21>0),"ERROR: en ambos días","")
A22: Cheesecake con salsa de fresa | B22: Dulce | C22: Dulce | D22: 1.4 | F22: 0 | G22: 1 | H22: =IF(AND(F22>0,G22>0),"ERROR: en ambos días","")
A23: Pie de limón | B23: Dulce | C23: Dulce | D23: 1.4 | F23: 1 | G23: 0 | H23: =IF(AND(F23>0,G23>0),"ERROR: en ambos días","")
A25: Checks (menú final)
A26: Día 1 - Saladas (debe = Inputs!B6) | B26: =SUMPRODUCT((B3:B23="Salado")*(F3:F23)) -> 8 | C26: =IF(ABS(B26-Inputs!$B$6)<0.001,"OK","REVISAR") -> OK | E26: Día 2 - Saladas (debe = Inputs!B6) | F26: =SUMPRODUCT((B3:B23="Salado")*(G3:G23)) -> 8 | G26: =IF(ABS(F26-Inputs!$B$6)<0.001,"OK","REVISAR") -> OK
A27: Día 1 - Dulces (debe = Inputs!B7) | B27: =SUMPRODUCT((B3:B23="Dulce")*(F3:F23)) -> 2 | C27: =IF(ABS(B27-Inputs!$B$7)<0.001,"OK","REVISAR") -> OK | E27: Día 2 - Dulces (debe = Inputs!B7) | F27: =SUMPRODUCT((B3:B23="Dulce")*(G3:G23)) -> 2 | G27: =IF(ABS(F27-Inputs!$B$7)<0.001,"OK","REVISAR") -> OK
A28: Día 1 - Variedades (debe <= 10) | B28: =COUNTIF(F3:F23,">0") -> 10 | C28: =IF(B28<=10,"OK","REVISAR") -> OK | E28: Día 2 - Variedades (debe <= 10) | F28: =COUNTIF(G3:G23,">0") -> 10 | G28: =IF(F28<=10,"OK","REVISAR") -> OK
A29: Duplicados entre días (debe = 0) | B29: =COUNTIF(H3:H23,"ERROR*") -> 0 | C29: =IF(B29=0,"OK","REVISAR") -> OK | E29: Observación | F29: Con 16 saladas únicas ya es viable 8 + 8 sin repetir.

Sheet Orden_y_Costos
A1: Orden de compra y costos - comparativo 400 vs 500
A3: Inputs clave | H3: Checks de consistencia
A4: Invitados Esc. A | B4: =Inputs!B3 -> 400 | H4: Día 1 Saladas PPG | I4: =Menu_Setup!B26 -> 8 | K4: Objetivo | L4: =Inputs!B6 -> 8 | N4: Estado | O4: =Menu_Setup!C26 -> OK
A5: Invitados Esc. B | B5: =Inputs!B4 -> 500 | H5: Día 1 Dulces PPG | I5: =Menu_Setup!B27 -> 2 | K5: Objetivo | L5: =Inputs!B7 -> 2 | N5: Estado | O5: =Menu_Setup!C27 -> OK
A6: Mín/variedad | B6: =Inputs!B8 -> 50 | H6: Día 1 Variedades | I6: =Menu_Setup!B28 -> 10 | K6: Máx | L6: 10 | N6: Estado | O6: =Menu_Setup!C28 -> OK
A7: Servicio | B7: =Inputs!B9 -> 0.1 | H7: Día 2 Saladas PPG | I7: =Menu_Setup!F26 -> 8 | K7: Objetivo | L7: =Inputs!B6 -> 8 | N7: Estado | O7: =Menu_Setup!G26 -> OK
H8: Día 2 Dulces PPG | I8: =Menu_Setup!F27 -> 2 | K8: Objetivo | L8: =Inputs!B7 -> 2 | N8: Estado | O8: =Menu_Setup!G27 -> OK
H9: Día 2 Variedades | I9: =Menu_Setup!F28 -> 10 | K9: Máx | L9: 10 | N9: Estado | O9: =Menu_Setup!G28 -> OK
H10: Duplicados | I10: =Menu_Setup!B29 -> 0 | K10: Objetivo | L10: 0 | N10: Estado | O10: =Menu_Setup!C29 -> OK
A12: Boca / Variedad | B12: Sabor | C12: Tipo | D12: Precio unitario | E12: Notas | F12: D1 PPG | G12: D2 PPG | H12: Qty D1 (400) | I12: Qty D1 (500) | J12: Costo D1 (400) | K12: Costo D1 (500) | L12: Qty D2 (400) | M12: Qty D2 (500) | N12: Costo D2 (400) | O12: Costo D2 (500) | P12: Flag
A13: =Menu_Setup!A3 -> Brocheta caprese con pesto | B13: =Menu_Setup!B3 -> Salado | C13: =Menu_Setup!C3 -> I | D13: =Menu_Setup!D3 -> 1.4 | E13: =IF(Menu_Setup!E3="","",Menu_Setup!E3) | F13: =Menu_Setup!F3 -> 1 | G13: =Menu_Setup!G3 -> 0 | H13: =IF($F13>0,MAX(Inputs!$B$8,ROUNDUP(Inputs!$B$3*$F13,0)),0) -> 400 | I13: =IF($F13>0,MAX(Inputs!$B$8,ROUNDUP(Inputs!$B$4*$F13,0)),0) -> 500 | J13: =$H13*$D13 -> 560 | K13: =$I13*$D13 -> 700 | L13: =IF($G13>0,MAX(Inputs!$B$8,ROUNDUP(Inputs!$B$3*$G13,0)),0) -> 0 | M13: =IF($G13>0,MAX(Inputs!$B$8,ROUNDUP(Inputs!$B$4*$G13,0)),0) -> 0 | N13: =$L13*$D13 -> 0 | O13: =$M13*$D13 -> 0 | P13: =IF(Menu_Setup!H3="","",Menu_Setup!H3)
A14: =Menu_Setup!A4 -> Bolitas de papa rellena de queso | B14: =Menu_Setup!B4 -> Salado | C14: =Menu_Setup!C4 -> I | D14: =Menu_Setup!D4 -> 1.4 | E14: =IF(Menu_Setup!E4="","",Menu_Setup!E4) | F14: =Menu_Setup!F4 -> 1 | G14: =Menu_Setup!G4 -> 0 | H14: =IF($F14>0,MAX(Inputs!$B$8,ROUNDUP(Inputs!$B$3*$F14,0)),0) -> 400 | I14: =IF($F14>0,MAX(Inputs!$B$8,ROUNDUP(Inputs!$B$4*$F14,0)),0) -> 500 | J14: =$H14*$D14 -> 560 | K14: =$I14*$D14 -> 700 | L14: =IF($G14>0,MAX(Inputs!$B$8,ROUNDUP(Inputs!$B$3*$G14,0)),0) -> 0 | M14: =IF($G14>0,MAX(Inputs!$B$8,ROUNDUP(Inputs!$B$4*$G14,0)),0) -> 0 | N14: =$L14*$D14 -> 0 | O14: =$M14*$D14 -> 0 | P14: =IF(Menu_Setup!H4="","",Menu_Setup!H4)
A15: =Menu_Setup!A5 -> Hongos al ajillo | B15: =Menu_Setup!B5 -> Salado | C15: =Menu_Setup!C5 -> I | D15: =Menu_Setup!D5 -> 1.4 | E15: =IF(Menu_Setup!E5="","",Menu_Setup!E5) | F15: =Menu_Setup!F5 -> 1 | G15: =Menu_Setup!G5 -> 0 | H15: =IF($F15>0,MAX(Inputs!$B$8,ROUNDUP(Inputs!$B$3*$F15,0)),0) -> 400 | I15: =IF($F15>0,MAX(Inputs!$B$8,ROUNDUP(Inputs!$B$4*$F15,0)),0) -> 500 | J15: =$H15*$D15 -> 560 | K15: =$I15*$D15 -> 700 | L15: =IF($G15>0,MAX(Inputs!$B$8,ROUNDUP(Inputs!$B$3*$G15,0)),0) -> 0 | M15: =IF($G15>0,MAX(Inputs!$B$8,ROUNDUP(Inputs!$B$4*$G15,0)),0) -> 0 | N15: =$L15*$D15 -> 0 | O15: =$M15*$D15 -> 0 | P15: =IF(Menu_Setup!H5="","",Menu_Setup!H5)
A16: =Menu_Setup!A6 -> Mini quiché de espinaca y queso | B16: =Menu_Setup!B6 -> Salado | C16: =Menu_Setup!C6 -> I | D16: =Menu_Setup!D6 -> 1.4 | E16: =IF(Menu_Setup!E6="","",Menu_Setup!E6) | F16: =Menu_Setup!F6 -> 1 | G16: =Menu_Setup!G6 -> 0 | H16: =IF($F16>0,MAX(Inputs!$B$8,ROUNDUP(Inputs!$B$3*$F16,0)),0) -> 400 | I16: =IF($F16>0,MAX(Inputs!$B$8,ROUNDUP(Inputs!$B$4*$F16,0)),0) -> 500 | J16: =$H16*$D16 -> 560 | K16: =$I16*$D16 -> 700 | L16: =IF($G16>0,MAX(Inputs!$B$8,ROUNDUP(Inputs!$B$3*$G16,0)),0) -> 0 | M16: =IF($G16>0,MAX(Inputs!$B$8,ROUNDUP(Inputs!$B$4*$G16,0)),0) -> 0 | N16: =$L16*$D16 -> 0 | O16: =$M16*$D16 -> 0 | P16: =IF(Menu_Setup!H6="","",Menu_Setup!H6)
A17: =Menu_Setup!A7 -> Crostini de melocotones asados y queso roquefort | B17: =Menu_Setup!B7 -> Salado | C17: =Menu_Setup!C7 -> II | D17: =Menu_Setup!D7 -> 1.7 | E17: =IF(Menu_Setup!E7="","",Menu_Setup!E7) | F17: =Menu_Setup!F7 -> 1 | G17: =Menu_Setup!G7 -> 0 | H17: =IF($F17>0,MAX(Inputs!$B$8,ROUNDUP(Inputs!$B$3*$F17,0)),0) -> 400 | I17: =IF($F17>0,MAX(Inputs!$B$8,ROUNDUP(Inputs!$B$4*$F17,0)),0) -> 500 | J17: =$H17*$D17 -> 680 | K17: =$I17*$D17 -> 850 | L17: =IF($G17>0,MAX(Inputs!$B$8,ROUNDUP(Inputs!$B$3*$G17,0)),0) -> 0 | M17: =IF($G17>0,MAX(Inputs!$B$8,ROUNDUP(Inputs!$B$4*$G17,0)),0) -> 0 | N17: =$L17*$D17 -> 0 | O17: =$M17*$D17 -> 0 | P17: =IF(Menu_Setup!H7="","",Menu_Setup!H7)
A18: =Menu_Setup!A8 -> Crostini de cebollas caramelizadas en maple con peras y queso brie | B18: =Menu_Setup!B8 -> Salado | C18: =Menu_Setup!C8 -> II | D18: =Menu_Setup!D8 -> 1.7 | E18: =IF(Menu_Setup!E8="","",Menu_Setup!E8) | F18: =Menu_Setup!F8 -> 1 | G18: =Menu_Setup!G8 -> 0 | H18: =IF($F18>0,MAX(Inputs!$B$8,ROUNDUP(Inputs!$B$3*$F18,0)),0) -> 400 | I18: =IF($F18>0,MAX(Inputs!$B$8,ROUNDUP(Inputs!$B$4*$F18,0)),0) -> 500 | J18: =$H18*$D18 -> 680 | K18: =$I18*$D18 -> 850 | L18: =IF($G18>0,MAX(Inputs!$B$8,ROUNDUP(Inputs!$B$3*$G18,0)),0) -> 0 | M18: =IF($G18>0,MAX(Inputs!$B$8,ROUNDUP(Inputs!$B$4*$G18,0)),0) -> 0 | N18: =$L18*$D18 -> 0 | O18: =$M18*$D18 -> 0 | P18: =IF(Menu_Setup!H8="","",Menu_Setup!H8)
A19: =Menu_Setup!A9 -> Costilla de cerdo en salsa barbacoa | B19: =Menu_Setup!B9 -> Salado | C19: =Menu_Setup!C9 -> II | D19: =Menu_Setup!D9 -> 1.7 | E19: =IF(Menu_Setup!E9="","",Menu_Setup!E9) -> Confirmar forma de servicio (porción / bocado). | F19: =Menu_Setup!F9 -> 1 | G19: =Menu_Setup!G9 -> 0 | H19: =IF($F19>0,MAX(Inputs!$B$8,ROUNDUP(Inputs!$B$3*$F19,0)),0) -> 400 | I19: =IF($F19>0,MAX(Inputs!$B$8,ROUNDUP(Inputs!$B$4*$F19,0)),0) -> 500 | J19: =$H19*$D19 -> 680 | K19: =$I19*$D19 -> 850 | L19: =IF($G19>0,MAX(Inputs!$B$8,ROUNDUP(Inputs!$B$3*$G19,0)),0) -> 0 | M19: =IF($G19>0,MAX(Inputs!$B$8,ROUNDUP(Inputs!$B$4*$G19,0)),0) -> 0 | N19: =$L19*$D19 -> 0 | O19: =$M19*$D19 -> 0 | P19: =IF(Menu_Setup!H9="","",Menu_Setup!H9)
A20: =Menu_Setup!A10 -> Bagel de salmón | B20: =Menu_Setup!B10 -> Salado | C20: =Menu_Setup!C10 -> Gourmet | D20: =Menu_Setup!D10 -> 2 | E20: =IF(Menu_Setup!E10="","",Menu_Setup!E10) | F20: =Menu_Setup!F10 -> 0 | G20: =Menu_Setup!G10 -> 1 | H20: =IF($F20>0,MAX(Inputs!$B$8,ROUNDUP(Inputs!$B$3*$F20,0)),0) -> 0 | I20: =IF($F20>0,MAX(Inputs!$B$8,ROUNDUP(Inputs!$B$4*$F20,0)),0) -> 0 | J20: =$H20*$D20 -> 0 | K20: =$I20*$D20 -> 0 | L20: =IF($G20>0,MAX(Inputs!$B$8,ROUNDUP(Inputs!$B$3*$G20,0)),0) -> 400 | M20: =IF($G20>0,MAX(Inputs!$B$8,ROUNDUP(Inputs!$B$4*$G20,0)),0) -> 500 | N20: =$L20*$D20 -> 800 | O20: =$M20*$D20 -> 1000 | P20: =IF(Menu_Setup!H10="","",Menu_Setup!H10)
A21: =Menu_Setup!A11 -> Mini ceviche de pescado peruano | B21: =Menu_Setup!B11 -> Salado | C21: =Menu_Setup!C11 -> Gourmet | D21: =Menu_Setup!D11 -> 2 | E21: =IF(Menu_Setup!E11="","",Menu_Setup!E11) | F21: =Menu_Setup!F11 -> 0 | G21: =Menu_Setup!G11 -> 1 | H21: =IF($F21>0,MAX(Inputs!$B$8,ROUNDUP(Inputs!$B$3*$F21,0)),0) -> 0 | I21: =IF($F21>0,MAX(Inputs!$B$8,ROUNDUP(Inputs!$B$4*$F21,0)),0) -> 0 | J21: =$H21*$D21 -> 0 | K21: =$I21*$D21 -> 0 | L21: =IF($G21>0,MAX(Inputs!$B$8,ROUNDUP(Inputs!$B$3*$G21,0)),0) -> 400 | M21: =IF($G21>0,MAX(Inputs!$B$8,ROUNDUP(Inputs!$B$4*$G21,0)),0) -> 500 | N21: =$L21*$D21 -> 800 | O21: =$M21*$D21 -> 1000 | P21: =IF(Menu_Setup!H11="","",Menu_Setup!H11)
A22: =Menu_Setup!A12 -> Mini ceviche de camarón | B22: =Menu_Setup!B12 -> Salado | C22: =Menu_Setup!C12 -> Gourmet | D22: =Menu_Setup!D12 -> 2 | E22: =IF(Menu_Setup!E12="","",Menu_Setup!E12) | F22: =Menu_Setup!F12 -> 0 | G22: =Menu_Setup!G12 -> 1 | H22: =IF($F22>0,MAX(Inputs!$B$8,ROUNDUP(Inputs!$B$3*$F22,0)),0) -> 0 | I22: =IF($F22>0,MAX(Inputs!$B$8,ROUNDUP(Inputs!$B$4*$F22,0)),0) -> 0 | J22: =$H22*$D22 -> 0 | K22: =$I22*$D22 -> 0 | L22: =IF($G22>0,MAX(Inputs!$B$8,ROUNDUP(Inputs!$B$3*$G22,0)),0) -> 400 | M22: =IF($G22>0,MAX(Inputs!$B$8,ROUNDUP(Inputs!$B$4*$G22,0)),0) -> 500 | N22: =$L22*$D22 -> 800 | O22: =$M22*$D22 -> 1000 | P22: =IF(Menu_Setup!H12="","",Menu_Setup!H12)
A23: =Menu_Setup!A13 -> Brocheta de pollo al estilo Thai | B23: =Menu_Setup!B13 -> Salado | C23: =Menu_Setup!C13 -> Gourmet | D23: =Menu_Setup!D13 -> 2 | E23: =IF(Menu_Setup!E13="","",Menu_Setup!E13) | F23: =Menu_Setup!F13 -> 1 | G23: =Menu_Setup!G13 -> 0 | H23: =IF($F23>0,MAX(Inputs!$B$8,ROUNDUP(Inputs!$B$3*$F23,0)),0) -> 400 | I23: =IF($F23>0,MAX(Inputs!$B$8,ROUNDUP(Inputs!$B$4*$F23,0)),0) -> 500 | J23: =$H23*$D23 -> 800 | K23: =$I23*$D23 -> 1000 | L23: =IF($G23>0,MAX(Inputs!$B$8,ROUNDUP(Inputs!$B$3*$G23,0)),0) -> 0 | M23: =IF($G23>0,MAX(Inputs!$B$8,ROUNDUP(Inputs!$B$4*$G23,0)),0) -> 0 | N23: =$L23*$D23 -> 0 | O23: =$M23*$D23 -> 0 | P23: =IF(Menu_Setup!H13="","",Menu_Setup!H13)
A24: =Menu_Setup!A14 -> Camarones empanizados con salsa tártara | B24: =Menu_Setup!B14 -> Salado | C24: =Menu_Setup!C14 -> Gourmet | D24: =Menu_Setup!D14 -> 2 | E24: =IF(Menu_Setup!E14="","",Menu_Setup!E14) | F24: =Menu_Setup!F14 -> 0 | G24: =Menu_Setup!G14 -> 1 | H24: =IF($F24>0,MAX(Inputs!$B$8,ROUNDUP(Inputs!$B$3*$F24,0)),0) -> 0 | I24: =IF($F24>0,MAX(Inputs!$B$8,ROUNDUP(Inputs!$B$4*$F24,0)),0) -> 0 | J24: =$H24*$D24 -> 0 | K24: =$I24*$D24 -> 0 | L24: =IF($G24>0,MAX(Inputs!$B$8,ROUNDUP(Inputs!$B$3*$G24,0)),0) -> 400 | M24: =IF($G24>0,MAX(Inputs!$B$8,ROUNDUP(Inputs!$B$4*$G24,0)),0) -> 500 | N24: =$L24*$D24 -> 800 | O24: =$M24*$D24 -> 1000 | P24: =IF(Menu_Setup!H14="","",Menu_Setup!H14)
A25: Mini Filet Mignon | B25: =Menu_Setup!B15 -> Salado | C25: =Menu_Setup!C15 -> Gourmet | D25: =Menu_Setup!D15 -> 2 | E25: =IF(Menu_Setup!E15="","",Menu_Setup!E15) -> Confirmar cómo se sirve (corte / salsa). | F25: =Menu_Setup!F15 -> 0 | G25: =Menu_Setup!G15 -> 1 | H25: =IF($F25>0,MAX(Inputs!$B$8,ROUNDUP(Inputs!$B$3*$F25,0)),0) -> 0 | I25: =IF($F25>0,MAX(Inputs!$B$8,ROUNDUP(Inputs!$B$4*$F25,0)),0) -> 0 | J25: =$H25*$D25 -> 0 | K25: =$I25*$D25 -> 0 | L25: =IF($G25>0,MAX(Inputs!$B$8,ROUNDUP(Inputs!$B$3*$G25,0)),0) -> 400 | M25: =IF($G25>0,MAX(Inputs!$B$8,ROUNDUP(Inputs!$B$4*$G25,0)),0) -> 500 | N25: =$L25*$D25 -> 800 | O25: =$M25*$D25 -> 1000 | P25: =IF(Menu_Setup!H15="","",Menu_Setup!H15)
A26: =Menu_Setup!A16 -> Rollitos de pepino o de berenjenas | B26: =Menu_Setup!B16 -> Salado | C26: =Menu_Setup!C16 -> Vegetarianos | D26: =Menu_Setup!D16 -> 2.25 | E26: =IF(Menu_Setup!E16="","",Menu_Setup!E16) | F26: =Menu_Setup!F16 -> 0 | G26: =Menu_Setup!G16 -> 1 | H26: =IF($F26>0,MAX(Inputs!$B$8,ROUNDUP(Inputs!$B$3*$F26,0)),0) -> 0 | I26: =IF($F26>0,MAX(Inputs!$B$8,ROUNDUP(Inputs!$B$4*$F26,0)),0) -> 0 | J26: =$H26*$D26 -> 0 | K26: =$I26*$D26 -> 0 | L26: =IF($G26>0,MAX(Inputs!$B$8,ROUNDUP(Inputs!$B$3*$G26,0)),0) -> 400 | M26: =IF($G26>0,MAX(Inputs!$B$8,ROUNDUP(Inputs!$B$4*$G26,0)),0) -> 500 | N26: =$L26*$D26 -> 900 | O26: =$M26*$D26 -> 1125 | P26: =IF(Menu_Setup!H16="","",Menu_Setup!H16)
A27: =Menu_Setup!A17 -> Vegetales temporizados o tomates cherry confitados | B27: =Menu_Setup!B17 -> Salado | C27: =Menu_Setup!C17 -> Vegetarianos | D27: =Menu_Setup!D17 -> 2.25 | E27: =IF(Menu_Setup!E17="","",Menu_Setup!E17) | F27: =Menu_Setup!F17 -> 0 | G27: =Menu_Setup!G17 -> 1 | H27: =IF($F27>0,MAX(Inputs!$B$8,ROUNDUP(Inputs!$B$3*$F27,0)),0) -> 0 | I27: =IF($F27>0,MAX(Inputs!$B$8,ROUNDUP(Inputs!$B$4*$F27,0)),0) -> 0 | J27: =$H27*$D27 -> 0 | K27: =$I27*$D27 -> 0 | L27: =IF($G27>0,MAX(Inputs!$B$8,ROUNDUP(Inputs!$B$3*$G27,0)),0) -> 400 | M27: =IF($G27>0,MAX(Inputs!$B$8,ROUNDUP(Inputs!$B$4*$G27,0)),0) -> 500 | N27: =$L27*$D27 -> 900 | O27: =$M27*$D27 -> 1125 | P27: =IF(Menu_Setup!H17="","",Menu_Setup!H17)
A28: =Menu_Setup!A18 -> Humus de colores | B28: =Menu_Setup!B18 -> Salado | C28: =Menu_Setup!C18 -> Vegetarianos | D28: =Menu_Setup!D18 -> 2.25 | E28: =IF(Menu_Setup!E18="","",Menu_Setup!E18) | F28: =Menu_Setup!F18 -> 0 | G28: =Menu_Setup!G18 -> 1 | H28: =IF($F28>0,MAX(Inputs!$B$8,ROUNDUP(Inputs!$B$3*$F28,0)),0) -> 0 | I28: =IF($F28>0,MAX(Inputs!$B$8,ROUNDUP(Inputs!$B$4*$F28,0)),0) -> 0 | J28: =$H28*$D28 -> 0 | K28: =$I28*$D28 -> 0 | L28: =IF($G28>0,MAX(Inputs!$B$8,ROUNDUP(Inputs!$B$3*$G28,0)),0) -> 400 | M28: =IF($G28>0,MAX(Inputs!$B$8,ROUNDUP(Inputs!$B$4*$G28,0)),0) -> 500 | N28: =$L28*$D28 -> 900 | O28: =$M28*$D28 -> 1125 | P28: =IF(Menu_Setup!H18="","",Menu_Setup!H18)
A29: =Menu_Setup!A19 -> Cardenal de fruta roja (preferible fresa) | B29: =Menu_Setup!B19 -> Dulce | C29: =Menu_Setup!C19 -> Dulce | D29: =Menu_Setup!D19 -> 1.4 | E29: =IF(Menu_Setup!E19="","",Menu_Setup!E19) | F29: =Menu_Setup!F19 -> 1 | G29: =Menu_Setup!G19 -> 0 | H29: =IF($F29>0,MAX(Inputs!$B$8,ROUNDUP(Inputs!$B$3*$F29,0)),0) -> 400 | I29: =IF($F29>0,MAX(Inputs!$B$8,ROUNDUP(Inputs!$B$4*$F29,0)),0) -> 500 | J29: =$H29*$D29 -> 560 | K29: =$I29*$D29 -> 700 | L29: =IF($G29>0,MAX(Inputs!$B$8,ROUNDUP(Inputs!$B$3*$G29,0)),0) -> 0 | M29: =IF($G29>0,MAX(Inputs!$B$8,ROUNDUP(Inputs!$B$4*$G29,0)),0) -> 0 | N29: =$L29*$D29 -> 0 | O29: =$M29*$D29 -> 0 | P29: =IF(Menu_Setup!H19="","",Menu_Setup!H19)
A30: =Menu_Setup!A20 -> Fresas cubiertas con chocolate | B30: =Menu_Setup!B20 -> Dulce | C30: =Menu_Setup!C20 -> Dulce | D30: =Menu_Setup!D20 -> 1.4 | E30: =IF(Menu_Setup!E20="","",Menu_Setup!E20) | F30: =Menu_Setup!F20 -> 0 | G30: =Menu_Setup!G20 -> 1 | H30: =IF($F30>0,MAX(Inputs!$B$8,ROUNDUP(Inputs!$B$3*$F30,0)),0) -> 0 | I30: =IF($F30>0,MAX(Inputs!$B$8,ROUNDUP(Inputs!$B$4*$F30,0)),0) -> 0 | J30: =$H30*$D30 -> 0 | K30: =$I30*$D30 -> 0 | L30: =IF($G30>0,MAX(Inputs!$B$8,ROUNDUP(Inputs!$B$3*$G30,0)),0) -> 400 | M30: =IF($G30>0,MAX(Inputs!$B$8,ROUNDUP(Inputs!$B$4*$G30,0)),0) -> 500 | N30: =$L30*$D30 -> 560 | O30: =$M30*$D30 -> 700 | P30: =IF(Menu_Setup!H20="","",Menu_Setup!H20)
A31: =Menu_Setup!A21 -> Mini tartas / mini alfajores | B31: =Menu_Setup!B21 -> Dulce | C31: =Menu_Setup!C21 -> Dulce | D31: =Menu_Setup!D21 -> 1.4 | E31: =IF(Menu_Setup!E21="","",Menu_Setup!E21) -> (Reserva / reemplazo opcional). | F31: =Menu_Setup!F21 -> 0 | G31: =Menu_Setup!G21 -> 0 | H31: =IF($F31>0,MAX(Inputs!$B$8,ROUNDUP(Inputs!$B$3*$F31,0)),0) -> 0 | I31: =IF($F31>0,MAX(Inputs!$B$8,ROUNDUP(Inputs!$B$4*$F31,0)),0) -> 0 | J31: =$H31*$D31 -> 0 | K31: =$I31*$D31 -> 0 | L31: =IF($G31>0,MAX(Inputs!$B$8,ROUNDUP(Inputs!$B$3*$G31,0)),0) -> 0 | M31: =IF($G31>0,MAX(Inputs!$B$8,ROUNDUP(Inputs!$B$4*$G31,0)),0) -> 0 | N31: =$L31*$D31 -> 0 | O31: =$M31*$D31 -> 0 | P31: =IF(Menu_Setup!H21="","",Menu_Setup!H21)
A32: =Menu_Setup!A22 -> Cheesecake con salsa de fresa | B32: =Menu_Setup!B22 -> Dulce | C32: =Menu_Setup!C22 -> Dulce | D32: =Menu_Setup!D22 -> 1.4 | E32: =IF(Menu_Setup!E22="","",Menu_Setup!E22) | F32: =Menu_Setup!F22 -> 0 | G32: =Menu_Setup!G22 -> 1 | H32: =IF($F32>0,MAX(Inputs!$B$8,ROUNDUP(Inputs!$B$3*$F32,0)),0) -> 0 | I32: =IF($F32>0,MAX(Inputs!$B$8,ROUNDUP(Inputs!$B$4*$F32,0)),0) -> 0 | J32: =$H32*$D32 -> 0 | K32: =$I32*$D32 -> 0 | L32: =IF($G32>0,MAX(Inputs!$B$8,ROUNDUP(Inputs!$B$3*$G32,0)),0) -> 400 | M32: =IF($G32>0,MAX(Inputs!$B$8,ROUNDUP(Inputs!$B$4*$G32,0)),0) -> 500 | N32: =$L32*$D32 -> 560 | O32: =$M32*$D32 -> 700 | P32: =IF(Menu_Setup!H22="","",Menu_Setup!H22)
A33: =Menu_Setup!A23 -> Pie de limón | B33: =Menu_Setup!B23 -> Dulce | C33: =Menu_Setup!C23 -> Dulce | D33: =Menu_Setup!D23 -> 1.4 | E33: =IF(Menu_Setup!E23="","",Menu_Setup!E23) | F33: =Menu_Setup!F23 -> 1 | G33: =Menu_Setup!G23 -> 0 | H33: =IF($F33>0,MAX(Inputs!$B$8,ROUNDUP(Inputs!$B$3*$F33,0)),0) -> 400 | I33: =IF($F33>0,MAX(Inputs!$B$8,ROUNDUP(Inputs!$B$4*$F33,0)),0) -> 500 | J33: =$H33*$D33 -> 560 | K33: =$I33*$D33 -> 700 | L33: =IF($G33>0,MAX(Inputs!$B$8,ROUNDUP(Inputs!$B$3*$G33,0)),0) -> 0 | M33: =IF($G33>0,MAX(Inputs!$B$8,ROUNDUP(Inputs!$B$4*$G33,0)),0) -> 0 | N33: =$L33*$D33 -> 0 | O33: =$M33*$D33 -> 0 | P33: =IF(Menu_Setup!H23="","",Menu_Setup!H23)
A36: Resumen Día 1
A37: Subtotal (400) | B37: =SUM(J13:J33) -> 6200 | D37: Subtotal (500) | E37: =SUM(K13:K33) -> 7750
A38: Servicio (400) | B38: =B37*Inputs!$B$9 -> 620 | D38: Servicio (500) | E38: =E37*Inputs!$B$9 -> 775
A39: Total (400) | B39: =B37*(1+Inputs!$B$9) -> 6820 | D39: Total (500) | E39: =E37*(1+Inputs!$B$9) -> 8525
A40: Costo pp (400) | B40: =B39/Inputs!$B$3 -> 17.05 | D40: Costo pp (500) | E40: =E39/Inputs!$B$4 -> 17.05
A43: Resumen Día 2
A44: Subtotal (400) | B44: =SUM(N13:N33) -> 7820 | D44: Subtotal (500) | E44: =SUM(O13:O33) -> 9775
A45: Servicio (400) | B45: =B44*Inputs!$B$9 -> 782 | D45: Servicio (500) | E45: =E44*Inputs!$B$9 -> 977.5
A46: Total (400) | B46: =B44*(1+Inputs!$B$9) -> 8602 | D46: Total (500) | E46: =E44*(1+Inputs!$B$9) -> 10752.5
...
